Workbook

Sheet group
A2: ETU003141 | B2: Steeve
A4: ETU003286 | B4: Yvan

Sheet liste des taches
A1: Ligne | B1: Catégorie | C1: Module | D1: Page | E1: Taches | F1: Type | G1: Qui | H1: Estimation | I1: Temps passé | J1: Reste à faire | K1: Avancement
A2: 1 | E2: Setup TODO (conception) | G2: ETU003141 | H2: 120 | I2: =detail_avancement!B2 -> 90 | J2: 0 | K2: =IF(I2/(I2+J2) < 100, I2/(I2+J2), 100) -> 1
A3: 2 | E3: Setup TODO (conception) | G3: ETU003286 | H3: 120 | I3: =detail_avancement!B3 -> 90 | J3: 0 | K3: =IF(I3/(I3+J3) < 100, I3/(I3+J3), 100) -> 1
A4: 3 | E4: Setup environnement (php) | G4: ETU003286 | H4: 10 | I4: =detail_avancement!B4 -> 5 | J4: 0 | K4: =IF(I4/(I4+J4) < 100, I4/(I4+J4), 100) -> 1
A5: 4 | B5: Backoffice | E5: Formulaire (date + titre + tinydocs textarea) | F5: Affichage | G5: ETU003286 | H5: 50 | I5: =detail_avancement!B5 -> 55 | J5: 0 | K5: =IF(I5/(I5+J5) < 100, I5/(I5+J5), 100) -> 1 | L5: Scenario 1: Creation arcticles: (cree BO et Read FO)
A6: 5 | B6: Backoffice | E6: Formulaire CSS | F6: Affichage | G6: ETU003286 | H6: 25 | I6: =detail_avancement!B6 -> 25 | J6: 0 | K6: =IF(I6/(I6+J6) < 100, I6/(I6+J6), 100) -> 1
A7: 6 | B7: Backoffice | E7: Fake test upload image | F7: Metier | G7: ETU003286 | H7: 10 | I7: =detail_avancement!B7 -> 2 | J7: 0 | K7: =IF(I7/(I7+J7) < 100, I7/(I7+J7), 100) -> 1
A8: 7 | B8: Frontoffice | E8: Liste des articles (html + css) | F8: Affichage | G8: ETU003286 | H8: 15 | I8: =detail_avancement!B8 -> 34 | J8: 0 | K8: =IF(I8/(I8+J8) < 100, I8/(I8+J8), 100) -> 1
A9: 8 | B9: Frontoffice | E9: Liste des articles | F9: Metier | G9: ETU003141 | H9: 10 | I9: =detail_avancement!B9 -> 5 | J9: 0 | K9: =IF(I9/(I9+J9) < 100, I9/(I9+J9), 100) -> 1
A10: 9 | B10: Backoffice | E10: Creation article (sans upload photo) | F10: Metier | G10: ETU003141 | H10: 10 | I10: =detail_avancement!B10 -> 25 | J10: 0 | K10: =IF(I10/(I10+J10) < 100, I10/(I10+J10), 100) -> 1
A11: 10 | B11: Backoffice | E11: Upload photo | F11: Metier | G11: ETU003141 | H11: 10 | I11: =detail_avancement!B11 -> 25 | J11: 0 | K11: =IF(I11/(I11+J11) < 100, I11/(I11+J11), 100) -> 1
A12: 11 | B12: Backoffice | E12: Upload photo | F12: Integration | G12: ETU003286 | H12: 10 | I12: =detail_avancement!B12 -> 120 | J12: 0 | K12: =IF(I12/(I12+J12) < 100, I12/(I12+J12), 100) -> 1
A13: 12 | B13: Backoffice | E13: Upload photo | F13: Integration | G13: ETU003141 | H13: 10 | I13: =detail_avancement!B13 -> 120 | J13: 0 | K13: =IF(I13/(I13+J13) < 100, I13/(I13+J13), 100) -> 1
A14: 13 | B14: Frontoffice | E14: Confirmation de creation d'article dans FO | F14: Integration | G14: ETU003286 | H14: 20 | I14: =detail_avancement!B14 -> 25 | J14: 0 | K14: =IF(I14/(I14+J14) < 100, I14/(I14+J14), 100) -> 1
A15: 14 | B15: Frontoffice | E15: Confirmation de creation d'article dans FO | F15: Integration | G15: ETU003141 | H15: 20 | I15: =detail_avancement!B15 -> 25 | J15: 0 | K15: =IF(I15/(I15+J15) < 100, I15/(I15+J15), 100) -> 1
A16: 15 | B16: Frontoffice | E16: Details articles | F16: Affichage | G16: ETU003141 | H16: 10 | I16: =detail_avancement!B16 -> 60 | J16: 0 | K16: =IF(I16/(I16+J16) < 100, I16/(I16+J16), 100) -> 1 | L16: Scenario-2: Mijery details articles (FO)
A17: 16 | B17: Frontoffice | E17: Extraction ID a partir de l'url de l'article | F17: Metier | G17: ETU003286 | H17: 10 | I17: =detail_avancement!B17 -> 15 | J17: 0 | K17: =IF(I17/(I17+J17) < 100, I17/(I17+J17), 100) -> 1
A18: 17 | B18: Frontoffice | E18: static Article getArticleById() | F18: Metier | G18: ETU003286 | H18: 5 | I18: =detail_avancement!B18 -> 25 | J18: 0 | K18: =IF(I18/(I18+J18) < 100, I18/(I18+J18), 100) -> 1
A19: 18 | B19: Frontoffice | E19: Details articles | F19: Integration | G19: ETU003141 | H19: 10 | I19: =detail_avancement!B18 -> 25 | J19: 0 | K19: =IF(I19/(I19+J19) < 100, I19/(I19+J19), 100) -> 1
A20: 19 | B20: Frontoffice | E20: Details articles | F20: Integration | G20: ETU003286 | H20: 10 | I20: =detail_avancement!B19 -> 25 | J20: 0 | K20: =IF(I20/(I20+J20) < 100, I20/(I20+J20), 100) -> 1
A21: 20 | E21: Ajout input date + navbar | F21: Affichage | G21: ETU003286 | H21: 2 | I21: =detail_avancement!B20 -> 15 | J21: 0 | K21: =IF(I21/(I21+J21) < 100, I21/(I21+J21), 100) -> 1 | L21: Scenario-3: Filtrage des articles par dates, default: now()
A22: 21 | E22: Filtre des articles | F22: Metier | G22: ETU003141 | H22: 10 | I22: =detail_avancement!B21 -> 10 | J22: 0 | K22: =IF(I22/(I22+J22) < 100, I22/(I22+J22), 100) -> 1
A23: 22 | E23: Filtre des articles | F23: Integration | G23: ETU003141 | H23: 10 | I23: =detail_avancement!B22 -> 10 | J23: 0 | K23: =IF(I23/(I23+J23) < 100, I23/(I23+J23), 100) -> 1
A24: 23 | E24: Filtre des articles | F24: Integration | G24: ETU003286 | H24: 10 | I24: =detail_avancement!B23 -> 10 | J24: 0 | K24: =IF(I24/(I24+J24) < 100, I24/(I24+J24), 100) -> 1
A25: 24 | B25: Backoffice | C25: auth | D25: /login | E25: Form login | F25: Affichage | G25: ETU003286 | H25: 10 | I25: =detail_avancement!B24 -> 8 | J25: 0 | K25: =IF(I25/(I25+J25) < 100, I25/(I25+J25), 100) -> 1 | L25: Scenario-4: Login
A26: 25 | C26: auth | D26: /login | E26: Metier login (librairie) | F26: Metier | G26: ETU003286 | H26: 10 | I26: =detail_avancement!B25 -> 40 | J26: 0 | K26: =IF(I26/(I26+J26) < 100, I26/(I26+J26), 100) -> 1
A27: 26 | C27: auth | D27: /login | E27: Seeder | F27: Metier | G27: ETU003286 | H27: 10 | I27: =detail_avancement!B26 -> 20 | J27: 0 | K27: =IF(I27/(I27+J27) < 100, I27/(I27+J27), 100) -> 1
A28: 27 | H28: 0 | I28: =detail_avancement!B27 -> 0 | J28: =H28 -> 0 | K28: =IF(I28/(I28+J28) < 100, I28/(I28+J28), 100) -> #DIV/0!
A29: 28 | H29: 0 | I29: =detail_avancement!B28 -> 0 | J29: =H29 -> 0 | K29: =IF(I29/(I29+J29) < 100, I29/(I29+J29), 100) -> #DIV/0!
A30: 29 | E30: Refactor project structure | G30: ETU003286 | H30: 10 | I30: =detail_avancement!B29 -> 25 | J30: 0 | K30: =IF(I30/(I30+J30) < 100, I30/(I30+J30), 100) -> 1
A31: 30 | E31: Refactor code | G31: ETU003141 | H31: 20 | I31: =detail_avancement!B30 -> 25 | J31: 0 | K31: =IF(I31/(I31+J31) < 100, I31/(I31+J31), 100) -> 1
A32: 31 | E32: Photo de couverture | F32: Front | G32: ETU003286 | H32: 10 | I32: =detail_avancement!B31 -> 5 | J32: 0 | K32: =IF(I32/(I32+J32) < 100, I32/(I32+J32), 100) -> 1
A33: 32 | E33: Photo de couverture | F33: Metier | G33: ETU003286 | H33: 10 | I33: =detail_avancement!B32 -> 25 | J33: 0 | K33: =IF(I33/(I33+J33) < 100, I33/(I33+J33), 100) -> 1
A34: 33 | E34: Sauvegarder photos articles | F34: Integration | G34: ETU003141 | H34: 10 | I34: =detail_avancement!B33 -> 25 | J34: 0 | K34: =IF(I34/(I34+J34) < 100, I34/(I34+J34), 100) -> 1
A35: 34 | C35: auth | D35: /login | E35: Auth session | F35: Metier | G35: ETU003286 | H35: 10 | I35: =detail_avancement!B34 -> 8 | J35: 0 | K35: =IF(I35/(I35+J35) < 100, I35/(I35+J35), 100) -> 1
A36: 35 | E36: CRUD article (UD historisees) | G36: ETU003286 | H36: 30 | I36: =detail_avancement!B35 -> 35 | J36: 0 | K36: =IF(I36/(I36+J36) < 100, I36/(I36+J36), 100) -> 1
A37: 36 | E37: SEO (meta - images - title @ header) | G37: ETU003141 | H37: 10 | I37: =detail_avancement!B36 -> 10 | J37: 0 | K37: =IF(I37/(I37+J37) < 100, I37/(I37+J37), 100) -> 1
A38: 37 | E38: Rewriting (ex: login) | G38: ETU003286 | H38: 25 | I38: =detail_avancement!B37 -> 13 | J38: 0 | K38: =IF(I38/(I38+J38) < 100, I38/(I38+J38), 100) -> 1
A39: 38 | E39: Optimisation (cache + gzip + minification + photos) | G39: ETU003141 | H39: 10 | I39: =detail_avancement!B38 -> 0 | J39: =H39 -> 10 | K39: =IF(I39/(I39+J39) < 100, I39/(I39+J39), 100) -> 0
A40: 39 | E40: Test lighthouse | G40: ETU003286 | H40: 10 | I40: =detail_avancement!B39 -> 0 | J40: =H40 -> 10 | K40: =IF(I40/(I40+J40) < 100, I40/(I40+J40), 100) -> 0
...

Sheet recap

Sheet avancement
A1: estimation total | B1: temps passé total | C1: reste à faire total | D1: avancement | E1: dépassement
A2: =SUM('liste des taches'!H:H) -> 942 | B2: =SUM('liste des taches'!I:I) -> 1253 | C2: =SUM('liste des taches'!J:J) -> 30 | D2: =(B2/(B2+C2)) -> 0.9766173 | E2: =((B2+C2)-A2)/A2 -> 0.36199575
C3: =C2/60 -> 0.5 | D3: heure

Sheet detail_avancement
A1: Ligne | B1: Total | C1: 46108 | D1: 46109 | E1: 46110 | F1: 46111 | G1: 46112 | H1: 46113 | I1: 46114 | J1: 46115 | K1: 46116 | L1: 46117
A2: 1 | B2: =SUM(C2:O2) -> 90 | D2: =30+30+30 -> 90
A3: 2 | B3: =SUM(C3:O3) -> 90 | D3: =30+30+30 -> 90
A4: 3 | B4: =SUM(C4:O4) -> 5 | C4: 5
A5: 4 | B5: =SUM(C5:O5) -> 55 | E5: =30+25 -> 55
A6: 5 | B6: =SUM(C6:O6) -> 25 | E6: 25
A7: 6 | B7: =SUM(C7:O7) -> 2 | E7: 2
A8: 7 | B8: =SUM(C8:O8) -> 34 | E8: =9+25 -> 34
A9: 8 | B9: =SUM(C9:O9) -> 5 | E9: 5
A10: 9 | B10: =SUM(C10:O10) -> 25 | E10: 25
A11: 10 | B11: =SUM(C11:O11) -> 25 | E11: 25
A12: 11 | B12: =SUM(C12:O12) -> 120 | F12: =60*2 -> 120
A13: 12 | B13: =SUM(C13:O13) -> 120 | F13: =60*2 -> 120
A14: 13 | B14: =SUM(C14:O14) -> 25 | F14: =25 -> 25
A15: 14 | B15: =SUM(C15:O15) -> 25 | F15: =25 -> 25
A16: 15 | B16: =SUM(C16:O16) -> 60 | F16: =60 -> 60
A17: 16 | B17: =SUM(C17:O17) -> 15 | F17: 15
A18: 17 | B18: =SUM(C18:O18) -> 25 | F18: 25
A19: 18 | B19: =SUM(C19:O19) -> 25 | F19: =F18 -> 25
A20: 19 | B20: =SUM(C20:O20) -> 15 | F20: 15
A21: 20 | B21: =SUM(C21:O21) -> 10 | G21: 10
A22: 21 | B22: =SUM(C22:O22) -> 10 | G22: 10
A23: 22 | B23: =SUM(C23:O23) -> 10 | G23: 10
A24: 23 | B24: =SUM(C24:O24) -> 8 | F24: 8
A25: 24 | B25: =SUM(C25:O25) -> 40 | E25: 15 | F25: 25
A26: 25 | B26: =SUM(C26:O26) -> 20 | F26: 20
A27: 26 | B27: =SUM(C27:O27) -> 0
A28: 27 | B28: =SUM(C28:O28) -> 0
A29: 28 | B29: =SUM(C29:O29) -> 25 | F29: 25
A30: 29 | B30: =SUM(C30:O30) -> 25 | F30: =25 -> 25
A31: 30 | B31: =SUM(C31:O31) -> 5 | F31: 5
A32: 31 | B32: =SUM(C32:O32) -> 25 | F32: 25
A33: 32 | B33: =SUM(C33:O33) -> 25 | F33: 25
A34: 33 | B34: =SUM(C34:O34) -> 8 | G34: 8
A35: 34 | B35: =SUM(C35:O35) -> 35 | G35: =25+10 -> 35
A36: 35 | B36: =SUM(C36:O36) -> 10 | G36: 10
A37: 36 | B37: =SUM(C37:O37) -> 13 | G37: 13
A38: 37 | B38: =SUM(C38:O38) -> 0
A39: 38 | B39: =SUM(C39:O39) -> 0
A40: 39 | B40: =SUM(D40:O40) -> 0
...
